Workbook

Sheet Resumen
A1: MalAPI.io — Exportación del catálogo de APIs de Windows usadas por malware
A2: Fuente: https://malapi.io/ (tabla principal + páginas /winapi/<API>). Extraído el 28/09/2026.
A4: Categoría | B4: APIs asignadas | C4: % del total de asignaciones
A5: Enumeration | B5: =COUNTIF(Mapeo_Categoria_API!$A:$A,A5) -> 73 | C5: =IFERROR(B5/$B$13,0) -> 0.17056075
A6: Injection | B6: =COUNTIF(Mapeo_Categoria_API!$A:$A,A6) -> 91 | C6: =IFERROR(B6/$B$13,0) -> 0.21261682
A7: Evasion | B7: =COUNTIF(Mapeo_Categoria_API!$A:$A,A7) -> 38 | C7: =IFERROR(B7/$B$13,0) -> 0.088785047
A8: Spying | B8: =COUNTIF(Mapeo_Categoria_API!$A:$A,A8) -> 29 | C8: =IFERROR(B8/$B$13,0) -> 0.067757009
A9: Internet | B9: =COUNTIF(Mapeo_Categoria_API!$A:$A,A9) -> 41 | C9: =IFERROR(B9/$B$13,0) -> 0.095794393
A10: Anti-Debugging | B10: =COUNTIF(Mapeo_Categoria_API!$A:$A,A10) -> 24 | C10: =IFERROR(B10/$B$13,0) -> 0.056074766
A11: Ransomware | B11: =COUNTIF(Mapeo_Categoria_API!$A:$A,A11) -> 21 | C11: =IFERROR(B11/$B$13,0) -> 0.049065421
A12: Helper | B12: =COUNTIF(Mapeo_Categoria_API!$A:$A,A12) -> 111 | C12: =IFERROR(B12/$B$13,0) -> 0.25934579
A13: Total asignaciones | B13: =SUM(B5:B12) -> 428 | C13: =SUM(C5:C12) -> 1
A14: APIs únicas | B14: =COUNTA(Catalogo_APIs!A2:A371) -> 370
A15: APIs en más de una categoría | B15: =SUMPRODUCT(--(COUNTIF(Mapeo_Categoria_API!$B$2:$B$429,Catalogo_APIs!A2:A371)>1)) -> 53
A17: Notas
A18: • Una misma API puede figurar en varias categorías; por eso el total de asignaciones supera las APIs únicas.
A19: • La columna "Categorías" sale de la tabla principal; algunas páginas individuales listan "Associated Attacks" distintos.
A20: • ReadFile: su página individual devolvió error 406 (Mod Security), así que no tiene librería ni descripción.
A21: • Textos de descripción tal como figuran en el sitio (en inglés), incluidos sus errores de tipeo.

Sheet Catalogo_APIs
A1: API | B1: Librería (DLL) | C1: Categorías (tabla principal) | D1: Enumeration | E1: Injection | F1: Evasion | G1: Spying | H1: Internet | I1: Anti-Debugging | J1: Ransomware | K1: Helper | L1: Descripción | M1: Documentación | N1: Creado | O1: Actualizado | P1: Créditos | Q1: URL MalAPI
A2: Accept | B2: Ws2_32.dll | C2: Internet | H2: X | L2: Accept is used to permit an incoming connection attempt on a socket. | M2: https://docs.microsoft.com/en-us/windows/win32/api/winsock2/nf-winsock2-accept | N2: 2021-10-30 | O2: 2021-10-30 | P2: mr.d0x | Q2: https://malapi.io/winapi/Accept
A3: AdjustTokenPrivileges | B3: Advapi32.dll | C3: Injection | E3: X | L3: AdjustTokenPrivileges is used to enable or disable specific access privileges. Malware that performs process injection often calls this function to gain additional permissions. | M3: https://docs.microsoft.com/en-us/windows/win32/api/securitybaseapi/nf-securitybaseapi-adjusttokenprivileges | N3: 2021-10-30 | O3: 2021-10-30 | P3: mr.d0x | Q3: https://malapi.io/winapi/AdjustTokenPrivileges
A4: AttachThreadInput | B4: User32.dll | C4: Spying | G4: X | L4: AttachThreadInput is used to attach the input processing from one thread to another so that the second thread receives input events such as keyboard and mouse events. This function is commonly used by keyloggers. | M4: https://docs.microsoft.com/en-us/windows/win32/api/winuser/nf-winuser-attachthreadinput | N4: 2021-10-30 | O4: 2021-10-30 | P4: mr.d0x | Q4: https://malapi.io/winapi/AttachThreadInput
A5: Bind | B5: Ws2_32.dll | C5: Internet | H5: X | L5: Bind is used to associates a local address with a socket. | M5: https://docs.microsoft.com/en-us/windows/win32/api/winsock2/nf-winsock2-bind | N5: 2021-10-30 | O5: 2021-10-30 | P5: mr.d0x | Q5: https://malapi.io/winapi/Bind
A6: BitBlt | B6: Gdi32.dll | C6: Spying | G6: X | L6: BitBlt is used to copy graphic data from one device to another. Spyware sometimes uses this function to capture screenshots. | M6: https://docs.microsoft.com/en-us/windows/win32/api/wingdi/nf-wingdi-bitblt | N6: 2021-10-30 | O6: 2021-10-30 | P6: mr.d0x | Q6: https://malapi.io/winapi/BitBlt
A7: BringWindowToTop | B7: User32.dll | C7: Helper | K7: X | L7: BringWindowToTop is used for bringing the specified window to the top of the Z order. | M7: https://docs.microsoft.com/en-us/windows/win32/api/winuser/nf-winuser-bringwindowtotop | N7: 2021-10-30 | O7: 2021-10-30 | P7: mr.d0x | Q7: https://malapi.io/winapi/BringWindowToTop
A8: CallNextHookEx | B8: User32.dll | C8: Spying | G8: X | L8: CallNextHookEx is used within code that is hooking an event set by SetWindowsHookEx. CallNextHookEx calls the next hook in the chain. This function is commonly used by keyloggers. | M8: https://docs.microsoft.com/en-us/windows/win32/api/winuser/nf-winuser-callnexthookex | N8: 2021-10-30 | O8: 2021-10-30 | P8: mr.d0x | Q8: https://malapi.io/winapi/CallNextHookEx
A9: CallWindowProcA | B9: User32.dll | C9: Helper | K9: X | L9: CallWindowProcA is used to pass message information to the specified window procedure. | M9: https://docs.microsoft.com/en-us/windows/win32/api/winuser/nf-winuser-callwindowproca | N9: 2021-11-02 | O9: 2021-11-02 | P9: @TalenceSecurity | Q9: https://malapi.io/winapi/CallWindowProcA
A10: CheckRemoteDebuggerPresent | B10: Kernel32.dll | C10: Anti-Debugging | I10: X | L10: CheckRemoteDebuggerPresent is used to check if a debugger is being used. This function is commonly used by malware for anti-debugging techniques. | M10: https://docs.microsoft.com/en-us/windows/win32/api/debugapi/nf-debugapi-checkremotedebuggerpresent | N10: 2021-10-30 | O10: 2021-10-30 | P10: mr.d0x | Q10: https://malapi.io/winapi/CheckRemoteDebuggerPresent
A11: Closesocket | B11: Ws2_32.dll | C11: Internet | H11: X | L11: Closesocket is used to close an existing socket. | M11: https://docs.microsoft.com/en-us/windows/win32/api/winsock/nf-winsock-closesocket | N11: 2021-11-02 | O11: 2021-11-02 | P11: Paul Melson - @pmelson | Q11: https://malapi.io/winapi/Closesocket
A12: Connect | B12: Ws2_32.dll | C12: Internet | H12: X | L12: Connect is used to establish a connection to a specified socket. | M12: https://docs.microsoft.com/en-us/windows/win32/api/winsock2/nf-winsock2-connect | N12: 2021-10-30 | O12: 2021-10-30 | P12: mr.d0x | Q12: https://malapi.io/winapi/Connect
A13: ConnectNamedPipe | B13: Kernel32.dll | C13: Helper | K13: X | L13: ConnectNamedPipe is used to create a server pipe for interprocess communication that will wait for a client pipe to connect. This function can be used to simplify connectivity to a C2 server. | M13: https://docs.microsoft.com/en-us/windows/win32/api/namedpipeapi/nf-namedpipeapi-connectnamedpipe | N13: 2021-10-30 | O13: 2021-10-30 | P13: mr.d0x | Q13: https://malapi.io/winapi/ConnectNamedPipe
A14: ControlService | B14: Advapi32.dll | C14: Helper | K14: X | L14: ControlService is used to start, stop, modify, or send a signal to a running service. This function is commonly used by malware went it requires interaction with a service for malicious purposes. | M14: https://docs.microsoft.com/en-us/windows/win32/api/winsvc/nf-winsvc-controlservice | N14: 2021-10-30 | O14: 2021-10-30 | P14: mr.d0x | Q14: https://malapi.io/winapi/ControlService
A15: ControlServiceExA | B15: Advapi32.dll | C15: Helper | K15: X | L15: ControlServiceExA is used to start, stop, modify, or send a signal to a running service. This function is commonly used by malware went it requires interaction with a service for malicious purposes. | M15: https://docs.microsoft.com/en-us/windows/win32/api/winsvc/nf-winsvc-controlserviceexa | N15: 2021-10-30 | O15: 2021-10-30 | P15: mr.d0x | Q15: https://malapi.io/winapi/ControlServiceExA
A16: CopyFile2 | B16: Kernel32.dll | C16: Helper | K16: X | L16: CopyFile2 is used to copy an existing file to a new file. | M16: https://docs.microsoft.com/en-us/windows/win32/api/winbase/nf-winbase-copyfile2 | N16: 2021-10-30 | O16: 2021-10-30 | P16: mr.d0x | Q16: https://malapi.io/winapi/CopyFile2
A17: CopyFileA | B17: Kernel32.dll | C17: Helper | K17: X | L17: CopyFileA is used to copy an existing file to a new file. | M17: https://docs.microsoft.com/en-us/windows/win32/api/winbase/nf-winbase-copyfilea | N17: 2021-10-30 | O17: 2021-10-30 | P17: mr.d0x | Q17: https://malapi.io/winapi/CopyFileA
A18: CopyFileExA | B18: Kernel32.dll | C18: Helper | K18: X | L18: CopyFileExA is used to copy an existing file to a new file. | M18: https://docs.microsoft.com/en-us/windows/win32/api/winbase/nf-winbase-copyfileexa | N18: 2021-10-30 | O18: 2021-10-30 | P18: mr.d0x | Q18: https://malapi.io/winapi/CopyFileExA
A19: CountClipboardFormats | B19: User32.dll | C19: Anti-Debugging | I19: X | L19: CountClipboardFormats is used to determine whether victim's clipboard was empty. A kind of Anti-debugging technique to determine if the system could be a sandbox. | M19: https://docs.microsoft.com/en-us/windows/win32/api/winuser/nf-winuser-countclipboardformats | N19: 2021-12-24 | O19: 2021-12-24 | P19: Jorge Testa - https://jorgetesta.tech | Q19: https://malapi.io/winapi/CountClipboardFormats
A20: CreateFile2 | B20: Kernel32.dll | C20: Helper | K20: X | L20: CreateFile2 is used to create a new file or opens an existing file. | M20: https://docs.microsoft.com/en-us/windows/win32/api/fileapi/nf-fileapi-createfile2 | N20: 2021-10-30 | O20: 2021-10-30 | P20: mr.d0x | Q20: https://malapi.io/winapi/CreateFile2
A21: CreateFileA | B21: Kernel32.dll | C21: Helper | K21: X | L21: CreateFileA is used to create a new file or opens an existing file. | M21: https://docs.microsoft.com/en-us/windows/win32/api/fileapi/nf-fileapi-createfilea | N21: 2021-10-30 | O21: 2021-10-30 | P21: mr.d0x | Q21: https://malapi.io/winapi/CreateFileA
A22: CreateFileMappingA | B22: Kernel32.dll | C22: Injection, Evasion | E22: X | F22: X | L22: CreateFileMappingA creates a handle to a file mapping that loads a file into memory and makes it accessible via memory addresses. Launchers, loaders, and injectors use this function to read and modify PE files. | M22: https://docs.microsoft.com/en-us/windows/win32/api/winbase/nf-winbase-createfilemappinga | N22: 2021-10-30 | O22: 2021-10-30 | P22: mr.d0x | Q22: https://malapi.io/winapi/CreateFileMappingA
A23: CreateMutexA | B23: Kernel32.dll | C23: Helper | K23: X | L23: CreateMutexA is used to create a new mutex object. Mutexs are often used by malware to prevent the reinfection of a system with the same or different malware variant. | M23: https://docs.microsoft.com/en-us/windows/win32/api/synchapi/nf-synchapi-createmutexa | N23: 2021-10-30 | O23: 2021-10-30 | P23: mr.d0x | Q23: https://malapi.io/winapi/CreateMutexA
A24: CreateMutexExA | B24: Kernel32.dll | C24: Helper | K24: X | L24: CreateMutexExA is used to create a new mutex object. Mutexs are often used by malware to prevent the reinfection of a system with the same or different malware variant. | M24: https://docs.microsoft.com/en-us/windows/win32/api/synchapi/nf-synchapi-createmutexexa | N24: 2021-10-30 | O24: 2021-10-30 | P24: mr.d0x | Q24: https://malapi.io/winapi/CreateMutexExA
A25: CreatePipe | B25: Kernel32.dll | C25: Helper | K25: X | L25: CreatePipe is used to create an anonymous pipe and returns handles to the read and write ends of the pipe. Could be used to add a sub-process for execution via cmd. | M25: https://docs.microsoft.com/en-us/windows/win32/api/namedpipeapi/nf-namedpipeapi-createpipe | N25: 2021-11-02 | O25: 2021-11-02 | P25: @TalenceSecurity | Q25: https://malapi.io/winapi/CreatePipe
A26: CreateProcessA | B26: Kernel32.dll | C26: Injection | E26: X | L26: CreateProcessA is used to create a process. This function is used by malware in several process injection attacks such as process hollowing. | M26: https://docs.microsoft.com/en-us/windows/win32/api/processthreadsapi/nf-processthreadsapi-createprocessa | N26: 2021-10-30 | O26: 2021-10-30 | P26: mr.d0x | Q26: https://malapi.io/winapi/CreateProcessA
A27: CreateProcessAsUserA | B27: Advapi32.dll | C27: Injection | E27: X | L27: CreateProcessAsUserA is used to create a new process and its primary thread. | M27: https://docs.microsoft.com/en-us/windows/win32/api/processthreadsapi/nf-processthreadsapi-createprocessasusera | N27: 2021-10-30 | O27: 2021-10-30 | P27: mr.d0x | Q27: https://malapi.io/winapi/CreateProcessAsUserA
A28: CreateProcessInternal | B28: Kernel32.dll | C28: Injection, Evasion | E28: X | F28: X | L28: CreateProcessInternal is an undocumented API for process creation. According to Windows Internals, CreateProcess and CreateProcessAsUser actually lead to this API, which is responsible for starting the process creation in user land. Eventually it calls NtCreateUserProcess for the kernel land operations. This API is commonly used for spawning a suspended process to be hollowed/injected. | M28: https://medium.com/@Achilles8284/the-birth-of-a-process-part-1-bfb4fdac070e | N28: 2022-03-27 | O28: 2022-03-27 | P28: InfoSecDodo - @dodo_sec | Q28: https://malapi.io/winapi/CreateProcessInternal
A29: CreateProcessWithTokenW | B29: Advapi32.dll | C29: Injection | E29: X | L29: CreateProcessWithTokenW is used to create a new process and its primary thread. | M29: https://docs.microsoft.com/en-us/windows/win32/api/winbase/nf-winbase-createprocesswithtokenw | N29: 2021-10-30 | O29: 2021-10-30 | P29: mr.d0x | Q29: https://malapi.io/winapi/CreateProcessWithTokenW
A30: CreateRemoteThread | B30: Kernel32.dll | C30: Injection | E30: X | L30: CreateRemoteThread is used to create a thread that runs in the virtual address space of another process. | M30: https://docs.microsoft.com/en-us/windows/win32/api/processthreadsapi/nf-processthreadsapi-createremotethread | N30: 2021-10-30 | O30: 2021-10-30 | P30: mr.d0x | Q30: https://malapi.io/winapi/CreateRemoteThread
A31: CreateRemoteThreadEx | B31: Kernel32.dll | C31: Injection | E31: X | L31: CreateRemoteThreadEx is used to create a thread that runs in the virtual address space of another process. | M31: https://docs.microsoft.com/en-us/windows/win32/api/processthreadsapi/nf-processthreadsapi-createremotethreadex | N31: 2021-10-30 | O31: 2021-10-30 | P31: mr.d0x | Q31: https://malapi.io/winapi/CreateRemoteThreadEx
A32: CreateServiceA | B32: Advapi32.dll | C32: Helper | K32: X | L32: CreateServiceA is used to create a service object and adds it to the specified service control manager database. This function is commonly used by malware for persistence. | M32: https://docs.microsoft.com/en-us/windows/win32/api/winsvc/nf-winsvc-createservicea | N32: 2021-10-30 | O32: 2021-10-30 | P32: mr.d0x | Q32: https://malapi.io/winapi/CreateServiceA
A33: CreateThread | B33: Kernel32.dll | C33: Injection | E33: X | L33: CreateThread is used to create a thread to execute within the virtual address space of the calling process. This function is commonly used for shellcode execution. | M33: https://docs.microsoft.com/en-us/windows/win32/api/processthreadsapi/nf-processthreadsapi-createthread | N33: 2021-10-30 | O33: 2021-10-30 | P33: mr.d0x | Q33: https://malapi.io/winapi/CreateThread
A34: CreateTimerQueueTimer | B34: Kernel32.dll | C34: Evasion | F34: X | L34: CreateTimerQueueTimer is used to create a timer-queue timer. This function is commonly used by malware for time-based evasion. | M34: https://docs.microsoft.com/en-us/windows/win32/api/threadpoollegacyapiset/nf-threadpoollegacyapiset-createtimerqueuetimer | N34: 2021-11-01 | O34: 2021-11-01 | P34: mr.d0x | Q34: https://malapi.io/winapi/CreateTimerQueueTimer
A35: CreateToolhelp32Snapshot | B35: Kernel32.dll | C35: Enumeration, Anti-Debugging | D35: X | I35: X | L35: CreateToolhelp32Snapshot is used to enumerate processes, threads, and modules. This function is commonly used by malware to enumerate processes before process injection. | M35: https://docs.microsoft.com/en-us/windows/win32/api/tlhelp32/nf-tlhelp32-createtoolhelp32snapshot | N35: 2021-10-30 | O35: 2021-10-30 | P35: mr.d0x | Q35: https://malapi.io/winapi/CreateToolhelp32Snapshot
A36: CreateWaitableTimer | B36: Kernel32.dll | C36: Evasion | F36: X | L36: CreateWaitableTimer is used to create a delay timer. This function is used by malware for time-based evasion. | M36: https://docs.microsoft.com/en-us/windows/win32/api/synchapi/nf-synchapi-createwaitabletimerw | N36: 2021-11-01 | O36: 2021-11-01 | P36: mr.d0x | Q36: https://malapi.io/winapi/CreateWaitableTimer
A37: CreateWindowExA | B37: User32.dll | C37: Evasion | F37: X | L37: CreateWindowExA is used to create an overlapped, pop-up, or child window with an extended window style. This function is commonly used by malware to create invisible windows or for evasion purposes. | M37: https://docs.microsoft.com/en-us/windows/win32/api/winuser/nf-winuser-createwindowexa | N37: 2021-10-30 | O37: 2021-10-30 | P37: mr.d0x | Q37: https://malapi.io/winapi/CreateWindowExA
A38: CryptAcquireContextA | B38: Advapi32.dll | C38: Ransomware | J38: X | L38: CryptAcquireContextA is used to acquire a handle to a particular key container within a particular cryptographic service provider (CSP) | M38: https://docs.microsoft.com/en-us/windows/win32/api/wincrypt/nf-wincrypt-cryptacquirecontexta | N38: 2021-10-30 | O38: 2021-10-30 | P38: mr.d0x | Q38: https://malapi.io/winapi/CryptAcquireContextA
A39: CryptBinaryToString | B39: Crypt32.dll | C39: Ransomware | J39: X | L39: The CryptBinaryToString function is used to convert an array of bytes into a formatted string. | M39: https://docs.microsoft.com/en-us/windows/win32/api/wincrypt/nf-wincrypt-cryptbinarytostringa | N39: 2021-12-24 | O39: 2021-12-24 | P39: mr.d0x | Q39: https://malapi.io/winapi/CryptBinaryToString
A40: CryptCreateHash | B40: Advapi32.dll | C40: Ransomware | J40: X | L40: CryptCreateHash is used to create a hash. | M40: https://docs.microsoft.com/en-us/windows/win32/api/wincrypt/nf-wincrypt-cryptcreatehash | N40: 2021-10-30 | O40: 2021-10-30 | P40: mr.d0x | Q40: https://malapi.io/winapi/CryptCreateHash
...

Sheet Mapeo_Categoria_API
A1: Categoría | B1: API | C1: Librería (DLL) | D1: Descripción
A2: Enumeration | B2: CreateToolhelp32Snapshot | C2: =IFERROR(INDEX(Catalogo_APIs!$B:$B,MATCH(B2,Catalogo_APIs!$A:$A,0)),"") -> Kernel32.dll | D2: =IFERROR(INDEX(Catalogo_APIs!$L:$L,MATCH(B2,Catalogo_APIs!$A:$A,0)),"") -> CreateToolhelp32Snapshot is used to enumerate processes, threads, and modules. This function is commonly used by malware to enumerate processes before process injection.
A3: Enumeration | B3: EnumDeviceDrivers | C3: =IFERROR(INDEX(Catalogo_APIs!$B:$B,MATCH(B3,Catalogo_APIs!$A:$A,0)),"") -> Kernel32.dll | D3: =IFERROR(INDEX(Catalogo_APIs!$L:$L,MATCH(B3,Catalogo_APIs!$A:$A,0)),"") -> EnumDeviceDrivers is used to enumerate drivers in the machine. This function is commonly used with kernel malware or for enumeration purposes.
A4: Enumeration | B4: EnumProcesses | C4: =IFERROR(INDEX(Catalogo_APIs!$B:$B,MATCH(B4,Catalogo_APIs!$A:$A,0)),"") -> Kernel32.dll | D4: =IFERROR(INDEX(Catalogo_APIs!$L:$L,MATCH(B4,Catalogo_APIs!$A:$A,0)),"") -> EnumProcesses is used to enumerate processes in the machine. Process enumeration is often a precursor to process injection.
A5: Enumeration | B5: EnumProcessModules | C5: =IFERROR(INDEX(Catalogo_APIs!$B:$B,MATCH(B5,Catalogo_APIs!$A:$A,0)),"") -> Kernel32.dll | D5: =IFERROR(INDEX(Catalogo_APIs!$L:$L,MATCH(B5,Catalogo_APIs!$A:$A,0)),"") -> EnumProcessModules is used to enumerate the loaded modules (executables and DLLs) for a given process. Malware enumerates through modules when doing injection.
A6: Enumeration | B6: EnumProcessModulesEx | C6: =IFERROR(INDEX(Catalogo_APIs!$B:$B,MATCH(B6,Catalogo_APIs!$A:$A,0)),"") -> Kernel32.dll | D6: =IFERROR(INDEX(Catalogo_APIs!$L:$L,MATCH(B6,Catalogo_APIs!$A:$A,0)),"") -> EnumProcessModulesEx is used to enumerate the loaded modules (executables and DLLs) for a given process. Malware enumerates through modules when doing injection.
A7: Enumeration | B7: FindFirstFileA | C7: =IFERROR(INDEX(Catalogo_APIs!$B:$B,MATCH(B7,Catalogo_APIs!$A:$A,0)),"") -> Kernel32.dll | D7: =IFERROR(INDEX(Catalogo_APIs!$L:$L,MATCH(B7,Catalogo_APIs!$A:$A,0)),"") -> FindFirstFileA is used to search through a directory and enumerate the filesystem.
A8: Enumeration | B8: FindNextFileA | C8: =IFERROR(INDEX(Catalogo_APIs!$B:$B,MATCH(B8,Catalogo_APIs!$A:$A,0)),"") -> Kernel32.dll | D8: =IFERROR(INDEX(Catalogo_APIs!$L:$L,MATCH(B8,Catalogo_APIs!$A:$A,0)),"") -> FindNextFileA is used to search through a directory and enumerate the filesystem.
A9: Enumeration | B9: GetLogicalProcessorInformation | C9: =IFERROR(INDEX(Catalogo_APIs!$B:$B,MATCH(B9,Catalogo_APIs!$A:$A,0)),"") -> Kernel32.dll | D9: =IFERROR(INDEX(Catalogo_APIs!$L:$L,MATCH(B9,Catalogo_APIs!$A:$A,0)),"") -> GetLogicalProcessorInformation is used to retrieve information about logical processors and related hardware. The function is used by malware for anti-debugging purposes.
A10: Enumeration | B10: GetLogicalProcessorInformationEx | C10: =IFERROR(INDEX(Catalogo_APIs!$B:$B,MATCH(B10,Catalogo_APIs!$A:$A,0)),"") -> Kernel32.dll | D10: =IFERROR(INDEX(Catalogo_APIs!$L:$L,MATCH(B10,Catalogo_APIs!$A:$A,0)),"") -> GetLogicalProcessorInformationEx is used to retrieve information about logical processors and related hardware. The function is used by malware for anti-debugging purposes.
A11: Enumeration | B11: GetModuleBaseNameA | C11: =IFERROR(INDEX(Catalogo_APIs!$B:$B,MATCH(B11,Catalogo_APIs!$A:$A,0)),"") -> Kernel32.dll | D11: =IFERROR(INDEX(Catalogo_APIs!$L:$L,MATCH(B11,Catalogo_APIs!$A:$A,0)),"") -> GetModuleBaseNameA is used to retrieve the base name of a specified module.
A12: Enumeration | B12: GetSystemDefaultLangId | C12: =IFERROR(INDEX(Catalogo_APIs!$B:$B,MATCH(B12,Catalogo_APIs!$A:$A,0)),"") -> Kernel32.dll | D12: =IFERROR(INDEX(Catalogo_APIs!$L:$L,MATCH(B12,Catalogo_APIs!$A:$A,0)),"") -> GetSystemDefaultLangId is used to retrieve the language identifier for the system. This function is used by malware that wish to infect specific locales or simply wish to gather statistics on areas of infection.
A13: Enumeration | B13: GetVersionExA | C13: =IFERROR(INDEX(Catalogo_APIs!$B:$B,MATCH(B13,Catalogo_APIs!$A:$A,0)),"") -> Kernel32.dll | D13: =IFERROR(INDEX(Catalogo_APIs!$L:$L,MATCH(B13,Catalogo_APIs!$A:$A,0)),"") -> GetVersionExA is a classic method used to retrieve the Windows version.
... A429: Helper | B429: UuidFromStringA | C429: =IFERROR(INDEX(Catalogo_APIs!$B:$B,MATCH(B429,Catalogo_APIs!$A:$A,0)),"") -> Rpcrt4.dll | D429: =IFERROR(INDEX(Catalogo_APIs!$L:$L,MATCH(B429,Catalogo_APIs!$A:$A,0)),"") -> UuidFromStringA is used to convert a string to a UUID. This function can be abused to both decode data and write it to memory without using common functions such as memcpy or WriteProcessMemory.
